Workbook
Name ENT: Data!$AB$4
Name USGS49: Data!$AB$3

Sheet Data
A1: OurLabID | B1: Sample ID | C1: Analysis_Date_Time | D1: d2H of injections | E1: d2H injections St Dev | F1: d2H of Analyses | G1: d2H injections St Dev | H1: d18O of injections | I1: d18O injections St Dev | J1: M Fl (mg) | K1: M USGS-49 (mg) | L1: M ENT (mg) | M1: XENT | N1: d18O Meas | O1: d18O Nominal | P1: (18O/16O)soln | Q1: d18O Fl | R1: Δ18O Fl | S1: d18O ISO | T1: M SiO2 (mg) | U1: M Qz sat. (mg) | V1: MO,MTZ (g) | W1: MMTZ (g) | X1: Solb (molality)
A2: W-3 | B2: DIW Wash | C2: 45485.791 | D2: -38.83 | E2: 0.08 | F2: -38.83 | H2: -6.34 | I2: 0.01 | N2: -6.34 | AA2: MT Z | AB2: d18O
A3: W-36 | B3: USGS 49 | C3: 45485.993 | D3: -394.7 | E3: 0.99 | F3: -394.7 | G3: 0 | H3: -50.55 | I3: 0.07 | N3: -50.55 | AA3: USGS49 | AB3: -50.55 | AC3: -50.55
A4: W-36 | B4: USGS 49 | C4: 45487.153 | D4: -394.7 | E4: 0.62 | F4: -394.7 | G4: 0 | H4: -50.55 | I4: 0.04 | N4: -50.55 | AA4: ENT | AB4: -6.59 | AC4: -6.59
A5: W-36 | B5: USGS 49 | C5: 45488.363 | D5: -394.7 | E5: 0.65 | F5: -394.7 | G5: 0 | H5: -50.55 | I5: 0.04 | N5: -50.55
A6: W-36 | B6: USGS 49 | C6: 45489.521 | D6: -394.7 | E6: 0.58 | F6: -394.7 | G6: 0 | H6: -50.55 | I6: 0.05 | N6: -50.55 | AA6: USGS49 meas | AB6: USGS49
A7: W-36 | B7: USGS 49 | C7: 45490.428 | D7: -394.7 | E7: 0.66 | F7: -394.7 | G7: 0 | H7: -50.55 | I7: 0.04 | N7: -50.55 | AA7: -50.55 | AB7: -50.55
A8: W-36 | B8: USGS 49 | C8: 45491.589 | D8: -394.7 | E8: 0.61 | F8: -394.7 | G8: 0 | H8: -50.55 | I8: 0.03 | N8: -50.55
A9: W-36 | B9: USGS 49 | C9: 45492.8 | D9: -394.7 | E9: 0.64 | F9: -394.7 | G9: 0 | H9: -50.55 | I9: 0.04 | N9: -50.55 | AA9: ENT meas | AB9: ENT
A10: W-36 | B10: USGS 49 | C10: 45493.959 | D10: -394.7 | E10: 0.73 | F10: -394.7 | G10: 0 | H10: -50.55 | I10: 0.06 | N10: -50.55 | AA10: -6.59 | AB10: -6.59
A11: W-36 | B11: USGS 49 | C11: 45494.866 | D11: -394.7 | E11: 0.77 | F11: -394.7 | G11: 0 | H11: -50.55 | I11: 0.09 | N11: -50.55
A12: W-37 | B12: USGS 50 | C12: 45486.144 | D12: 32.8 | E12: 0.16 | F12: 32.8 | G12: 0 | H12: 4.95 | I12: 0.02 | N12: 4.95 | AA12: (18O/16O)SMOW | AB12: =0.0020052 -> 0.0020052
A13: W-37 | B13: USGS 50 | C13: 45487.254 | D13: 32.8 | E13: 0.4 | F13: 32.8 | G13: 0 | H13: 4.95 | I13: 0.04 | N13: 4.95
A14: W-37 | B14: USGS 50 | C14: 45488.464 | D14: 32.8 | E14: 0.43 | F14: 32.8 | G14: 0 | H14: 4.95 | I14: 0.03 | N14: 4.95
A15: W-37 | B15: USGS 50 | C15: 45489.572 | D15: 32.8 | E15: 1.03 | F15: 32.8 | G15: 0 | H15: 4.95 | I15: 0.06 | N15: 4.95
A16: W-37 | B16: USGS 50 | C16: 45490.579 | D16: 32.8 | E16: 0.18 | F16: 32.8 | G16: 0 | H16: 4.95 | I16: 0.02 | N16: 4.95
A17: W-37 | B17: USGS 50 | C17: 45491.69 | D17: 32.8 | E17: 0.37 | F17: 32.8 | G17: 0 | H17: 4.95 | I17: 0.03 | N17: 4.95
A18: W-37 | B18: USGS 50 | C18: 45492.9 | D18: 32.8 | E18: 0.31 | F18: 32.8 | G18: 0 | H18: 4.95 | I18: 0.04 | N18: 4.95
A19: W-37 | B19: USGS 50 | C19: 45494.009 | D19: 32.8 | E19: 1.04 | F19: 32.8 | G19: 0 | H19: 4.95 | I19: 0.09 | N19: 4.95
A20: W-37 | B20: USGS 50 | C20: 45495.018 | D20: 32.8 | E20: 0.14 | F20: 32.8 | G20: 0 | H20: 4.95 | I20: 0.02 | N20: 4.95
A21: W-998 | B21: DI for linearity evaluation | C21: 45485.842 | D21: -38.66 | E21: 0.04 | F21: -38.65 | G21: 0.02 | H21: -6.35 | I21: 0.03 | N21: -6.34
A22: W-998 | B22: DI for linearity evaluation | C22: 45485.892 | D22: -38.63 | E22: 0.05 | F22: -38.65 | G22: 0.02 | H22: -6.32 | I22: 0.02 | N22: -6.34
A23: W-998 | B23: DI for linearity evaluation | C23: 45485.942 | D23: -38.67 | E23: 0.04 | F23: -38.65 | G23: 0.02 | H23: -6.36 | I23: 0.01 | N23: -6.34
A24: W-2366 | B24: Zircon009 RP-1 | C24: 45486.17 | D24: -40.45 | E24: 0.13 | F24: -40.34 | G24: 0.16 | H24: -7.71 | I24: 0.03 | J24: 104.0568 | K24: 120 | L24: 2400 | M24: =L24/(L24+J24) -> 0.95844471 | N24: -7.7 | O24: =M24*ENT+(1-M24)*USGS49 -> -8.4167704 | P24: =N24*0.001*AB$12+AB$12 -> 0.00198976 | Q24: =((J24+L24)*N24-L24*ENT)/J24 -> -33.301402 | R24: =Q24-USGS49 -> 17.248598 | S24: -19.25 | T24: =115.9289-114.8693 -> 1.0596 | U24: 1.488 | V24: =(((16/18)*K24/1000+(32/61)*T24/1000)*Q24-(16/18)*(K24/1000)*USGS49-(32/61)*(T24/1000)*S24)/4.93 -> 0.37161052 | W24: =V24*183.3/(4*16) -> 1.0643158 | X24: =1000000*W24/183.3 -> 5806.4144
A25: W-2366 | B25: Zircon009 RP-1 | C25: 45490.605 | D25: -40.22 | E25: 0.42 | F25: -40.34 | G25: 0.16 | H25: -7.69 | I25: 0.04 | J25: 104.0568 | K25: 120 | L25: 2400 | M25: =L25/(L25+J25) -> 0.95844471 | N25: -7.7 | O25: =M25*ENT+(1-M25)*USGS49 -> -8.4167704 | P25: =N25*0.001*AB$12+AB$12 -> 0.00198976 | Q25: =((J25+L25)*N25-L25*ENT)/J25 -> -33.301402 | R25: =Q25-USGS49 -> 17.248598 | S25: -19.25 | T25: =115.9289-114.8693 -> 1.0596 | U25: 1.488 | V25: =(((16/18)*K25/1000+(32/61)*T25/1000)*Q25-(16/18)*(K25/1000)*USGS49-(32/61)*(T25/1000)*S25)/4.93 -> 0.37161052 | W25: =V25*183.3/(4*16) -> 1.0643158 | X25: =1000000*W25/183.3 -> 5806.4144
A26: W-2367 | B26: Zircon014 RP-2 | C26: 45486.22 | D26: -44.86 | E26: 0.08 | F26: -44.75 | G26: 0.16 | H26: -7.71 | I26: 0.01 | J26: =1936.391-1798.5588 -> 137.8322 | K26: 120 | L26: =(4.3729-1.929)*1000 -> 2443.9 | M26: =L26/(L26+J26) -> 0.94661251 | N26: -7.69 | O26: =M26*ENT+(1-M26)*USGS49 -> -8.936914 | P26: =N26*0.001*AB$12+AB$12 -> 0.00198978 | Q26: =((J26+L26)*N26-L26*ENT)/J26 -> -27.194078 | R26: =Q26-USGS49 -> 23.355922 | S26: -19.25 | T26: 1.768 | U26: 1.7136 | V26: =(((16/18)*K26/1000+(32/61)*T26/1000)*Q26-(16/18)*(K26/1000)*USGS49-(32/61)*(T26/1000)*S26)/4.93 -> 0.50383984 | W26: =V26*183.3/(4*16) -> 1.4430288 | X26: =1000000*W26/183.3 -> 7872.4974
A27: W-2367 | B27: Zircon014 RP-2 | C27: 45490.656 | D27: -44.63 | E27: 0.05 | F27: -44.75 | G27: 0.16 | H27: -7.68 | I27: 0.01 | J27: =1936.391-1798.5588 -> 137.8322 | K27: 120 | L27: =(4.3729-1.929)*1000 -> 2443.9 | M27: =L27/(L27+J27) -> 0.94661251 | N27: -7.69 | O27: =M27*ENT+(1-M27)*USGS49 -> -8.936914 | P27: =N27*0.001*AB$12+AB$12 -> 0.00198978 | Q27: =((J27+L27)*N27-L27*ENT)/J27 -> -27.194078 | R27: =Q27-USGS49 -> 23.355922 | S27: -19.25 | T27: 1.768 | U27: 1.7136 | V27: =(((16/18)*K27/1000+(32/61)*T27/1000)*Q27-(16/18)*(K27/1000)*USGS49-(32/61)*(T27/1000)*S27)/4.93 -> 0.50383984 | W27: =V27*183.3/(4*16) -> 1.4430288 | X27: =1000000*W27/183.3 -> 7872.4974
A28: W-2368 | B28: Zircon015 RP-3 | C28: 45486.271 | D28: -40.89 | E28: 0.03 | F28: -40.71 | G28: 0.25 | H28: -4.82 | I28: 0.02 | J28: =1995.624-1796.2349 -> 199.3891 | K28: 120 | L28: =(4.4137-1.9956)*1000 -> 2418.1 | M28: =L28/(L28+J28) -> 0.92382429 | N28: -4.81 | O28: =M28*ENT+(1-M28)*USGS49 -> -9.9386844 | P28: =N28*0.001*AB$12+AB$12 -> 0.001995555 | Q28: =((J28+L28)*N28-L28*ENT)/J28 -> 16.777028 | R28: =Q28-USGS49 -> 67.327028 | S28: -19.25 | T28: 1.695 | U28: 1.7136 | V28: =(((16/18)*K28/1000+(32/61)*T28/1000)*Q28-(16/18)*(K28/1000)*USGS49-(32/61)*(T28/1000)*S28)/4.93 -> 1.4632016 | W28: =V28*183.3/(4*16) -> 4.190701 | X28: =1000000*W28/183.3 -> 22862.526
A29: W-2368 | B29: Zircon015 RP-3 | C29: 45490.706 | D29: -40.54 | E29: 0.32 | F29: -40.71 | G29: 0.25 | H29: -4.8 | I29: 0.03 | J29: =1995.624-1796.2349 -> 199.3891 | K29: 120 | L29: =(4.4137-1.9956)*1000 -> 2418.1 | M29: =L29/(L29+J29) -> 0.92382429 | N29: -4.81 | O29: =M29*ENT+(1-M29)*USGS49 -> -9.9386844 | P29: =N29*0.001*AB$12+AB$12 -> 0.001995555 | Q29: =((J29+L29)*N29-L29*ENT)/J29 -> 16.777028 | R29: =Q29-USGS49 -> 67.327028 | S29: -19.25 | T29: 1.695 | U29: 1.7136 | V29: =(((16/18)*K29/1000+(32/61)*T29/1000)*Q29-(16/18)*(K29/1000)*USGS49-(32/61)*(T29/1000)*S29)/4.93 -> 1.4632016 | W29: =V29*183.3/(4*16) -> 4.190701 | X29: =1000000*W29/183.3 -> 22862.526
A30: W-2369 | B30: Zircon017 RP-4 | C30: 45486.321 | D30: -52.76 | E30: 0.08 | F30: -52.57 | G30: 0.27 | H30: -7.83 | I30: 0.02 | J30: =1880.3652-1810.4256 -> 69.9396 | K30: 120 | L30: =(4.2863-1.8819)*1000 -> 2404.4 | M30: =L30/(L30+J30) -> 0.97173403 | N30: -7.83 | O30: =M30*ENT+(1-M30)*USGS49 -> -7.8325719 | P30: =N30*0.001*AB$12+AB$12 -> 0.0019894993 | Q30: =((J30+L30)*N30-L30*ENT)/J30 -> -50.459011 | R30: =Q30-USGS49 -> 0.090988682 | S30: -19.25 | T30: =152.1043-150.8015 -> 1.3028 | U30: 1.7136 | V30: =(((16/18)*K30/1000+(32/61)*T30/1000)*Q30-(16/18)*(K30/1000)*USGS49-(32/61)*(T30/1000)*S30)/4.93 -> -0.00235779 | W30: =V30*183.3/(4*16) -> -0.0067528578 | X30: =1000000*W30/183.3 -> -36.840468
A31: W-2369 | B31: Zircon017 RP-4 | C31: 45490.757 | D31: -52.38 | E31: 0.31 | F31: -52.57 | G31: 0.27 | H31: -7.83 | I31: 0.06 | J31: =1880.3652-1810.4256 -> 69.9396 | K31: 120 | L31: =(4.2863-1.8819)*1000 -> 2404.4 | M31: =L31/(L31+J31) -> 0.97173403 | N31: -7.83 | O31: =M31*ENT+(1-M31)*USGS49 -> -7.8325719 | P31: =N31*0.001*AB$12+AB$12 -> 0.0019894993 | Q31: =((J31+L31)*N31-L31*ENT)/J31 -> -50.459011 | R31: =Q31-USGS49 -> 0.090988682 | S31: -19.25 | T31: =152.1043-150.8015 -> 1.3028 | U31: 1.7136 | V31: =(((16/18)*K31/1000+(32/61)*T31/1000)*Q31-(16/18)*(K31/1000)*USGS49-(32/61)*(T31/1000)*S31)/4.93 -> -0.00235779 | W31: =V31*183.3/(4*16) -> -0.0067528578 | X31: =1000000*W31/183.3 -> -36.840468
A32: W-2370 | B32: Zircon019 RP-5 | C32: 45486.372 | D32: -50.1 | E32: 0.1 | F32: -49.94 | G32: 0.24 | H32: -7.47 | I32: 0.01 | J32: =1858.196-1804.0966 -> 54.0994 | K32: 120 | L32: 2400 | M32: =L32/(L32+J32) -> 0.9779555 | N32: -7.46 | O32: =M32*ENT+(1-M32)*USGS49 -> -7.5590763 | P32: =N32*0.001*AB$12+AB$12 -> 0.0019902412 | Q32: =((J32+L32)*N32-L32*ENT)/J32 -> -46.055622 | R32: =Q32-USGS49 -> 4.4943779 | S32: -19.25 | T32: =125.8417-124.2025 -> 1.6392 | U32: 0.8712 | V32: =(((16/18)*K32/1000+(32/61)*T32/1000)*Q32-(16/18)*(K32/1000)*USGS49-(32/61)*(T32/1000)*S32)/4.93 -> 0.092565909 | W32: =V32*183.3/(4*16) -> 0.26511455 | X32: =1000000*W32/183.3 -> 1446.3423
A33: W-2370 | B33: Zircon019 RP-5 | C33: 45490.807 | D33: -49.77 | E33: 0.04 | F33: -49.94 | G33: 0.24 | H33: -7.45 | I33: 0.02 | J33: =1858.196-1804.0966 -> 54.0994 | K33: 120 | L33: 2400 | M33: =L33/(L33+J33) -> 0.9779555 | N33: -7.46 | O33: =M33*ENT+(1-M33)*USGS49 -> -7.5590763 | P33: =N33*0.001*AB$12+AB$12 -> 0.0019902412 | Q33: =((J33+L33)*N33-L33*ENT)/J33 -> -46.055622 | R33: =Q33-USGS49 -> 4.4943779 | S33: -19.25 | T33: =125.8417-124.2025 -> 1.6392 | U33: 0.8712 | V33: =(((16/18)*K33/1000+(32/61)*T33/1000)*Q33-(16/18)*(K33/1000)*USGS49-(32/61)*(T33/1000)*S33)/4.93 -> 0.092565909 | W33: =V33*183.3/(4*16) -> 0.26511455 | X33: =1000000*W33/183.3 -> 1446.3423
A34: W-2371 | B34: Zircon021 RP-6 | C34: 45486.422 | D34: -41.68 | E34: 0.07 | F34: -41.48 | G34: 0.28 | H34: -6.39 | I34: 0.03 | J34: =1942.906-1781.8958 -> 161.0102 | K34: 120 | L34: 2400 | M34: =L34/(L34+J34) -> 0.9371302 | N34: -6.37 | O34: =M34*ENT+(1-M34)*USGS49 -> -9.3537564 | P34: =N34*0.001*AB$12+AB$12 -> 0.0019924269 | Q34: =((J34+L34)*N34-L34*ENT)/J34 -> -3.0907047 | R34: =Q34-USGS49 -> 47.459295 | S34: -19.25 | T34: =(174.4643-173.1019)+(1735.9271-1733.7685) -> 3.521 | U34: 1.7136 | V34: =(((16/18)*K34/1000+(32/61)*T34/1000)*Q34-(16/18)*(K34/1000)*USGS49-(32/61)*(T34/1000)*S34)/4.93 -> 1.032895 | W34: =V34*183.3/(4*16) -> 2.9582759 | X34: =1000000*W34/183.3 -> 16138.984 | AA34: Min | AB34: =MIN(R24:R48) -> 0.090988682
A35: W-2371 | B35: Zircon021 RP-6 | C35: 45490.858 | D35: -41.28 | E35: 0.12 | F35: -41.48 | G35: 0.28 | H35: -6.36 | I35: 0.01 | J35: =1942.906-1781.8958 -> 161.0102 | K35: 120 | L35: 2400 | M35: =L35/(L35+J35) -> 0.9371302 | N35: -6.37 | O35: =M35*ENT+(1-M35)*USGS49 -> -9.3537564 | P35: =N35*0.001*AB$12+AB$12 -> 0.0019924269 | Q35: =((J35+L35)*N35-L35*ENT)/J35 -> -3.0907047 | R35: =Q35-USGS49 -> 47.459295 | S35: -19.25 | T35: =(174.4643-173.1019)+(1735.9271-1733.7685) -> 3.521 | U35: 1.7136 | V35: =(((16/18)*K35/1000+(32/61)*T35/1000)*Q35-(16/18)*(K35/1000)*USGS49-(32/61)*(T35/1000)*S35)/4.93 -> 1.032895 | W35: =V35*183.3/(4*16) -> 2.9582759 | X35: =1000000*W35/183.3 -> 16138.984 | AA35: Mean d18O shift | AB35: =AVERAGE(R24:R48) -> 24.787028
A36: W-2372 | B36: Zircon022 RP-7 | C36: 45486.473 | D36: -40.77 | E36: 0.05 | F36: -40.57 | G36: 0.29 | H36: -6.74 | I36: 0.01 | J36: =1859.917-1779.875 -> 80.042 | K36: 120 | L36: =(4.2054-1.835)*1000 -> 2370.4 | M36: =L36/(L36+J36) -> 0.96733569 | N36: -6.72 | O36: =M36*ENT+(1-M36)*USGS49 -> -8.0259231 | P36: =N36*0.001*AB$12+AB$12 -> 0.0019917251 | Q36: =((J36+L36)*N36-L36*ENT)/J36 -> -10.569879 | R36: =Q36-USGS49 -> 39.980121 | S36: -19.25 | T36: =(175.9563-174.854)+(1727.6003-1726.7132) -> 1.9894 | U36: 1.7136 | V36: =(((16/18)*K36/1000+(32/61)*T36/1000)*Q36-(16/18)*(K36/1000)*USGS49-(32/61)*(T36/1000)*S36)/4.93 -> 0.866857 | W36: =V36*183.3/(4*16) -> 2.4827326 | X36: =1000000*W36/183.3 -> 13544.641 | AA36: Max | AB36: =MAX(R24:R48) -> 67.327028
A37: W-2372 | B37: Zircon022 RP-7 | C37: 45490.908 | D37: -40.37 | E37: 0.05 | F37: -40.57 | G37: 0.29 | H37: -6.69 | I37: 0.02 | J37: =1859.917-1779.875 -> 80.042 | K37: 120 | L37: =(4.2054-1.835)*1000 -> 2370.4 | M37: =L37/(L37+J37) -> 0.96733569 | N37: -6.72 | O37: =M37*ENT+(1-M37)*USGS49 -> -8.0259231 | P37: =N37*0.001*AB$12+AB$12 -> 0.0019917251 | Q37: =((J37+L37)*N37-L37*ENT)/J37 -> -10.569879 | R37: =Q37-USGS49 -> 39.980121 | S37: -19.25 | T37: =(175.9563-174.854)+(1727.6003-1726.7132) -> 1.9894 | U37: 1.7136 | V37: =(((16/18)*K37/1000+(32/61)*T37/1000)*Q37-(16/18)*(K37/1000)*USGS49-(32/61)*(T37/1000)*S37)/4.93 -> 0.866857 | W37: =V37*183.3/(4*16) -> 2.4827326 | X37: =1000000*W37/183.3 -> 13544.641
A38: W-2373 | B38: Zircon010 RP-8 | C38: 45486.523 | D38: -43.12 | E38: 0.14 | F38: -42.95 | G38: 0.24 | H38: -7.77 | I38: 0.01 | J38: =1874.2572-1777.9436 -> 96.3136 | K38: 120 | L38: 2400 | M38: =L38/(L38+J38) -> 0.96141767 | N38: -7.74 | O38: =M38*ENT+(1-M38)*USGS49 -> -8.2860793 | P38: =N38*0.001*AB$12+AB$12 -> 0.0019896798 | Q38: =((J38+L38)*N38-L38*ENT)/J38 -> -36.396389 | R38: =Q38-USGS49 -> 14.153611 | S38: -19.25 | T38: =174.3108-173.1998 -> 1.111 | U38: 1.488 | V38: =(((16/18)*K38/1000+(32/61)*T38/1000)*Q38-(16/18)*(K38/1000)*USGS49-(32/61)*(T38/1000)*S38)/4.93 -> 0.3042039 | W38: =V38*183.3/(4*16) -> 0.87125899 | X38: =1000000*W38/183.3 -> 4753.186
A39: W-2373 | B39: Zircon010 RP-8 | C39: 45490.959 | D39: -42.78 | E39: 0.23 | F39: -42.95 | G39: 0.24 | H39: -7.72 | I39: 0.03 | J39: =1874.2572-1777.9436 -> 96.3136 | K39: 120 | L39: 2400 | M39: =L39/(L39+J39) -> 0.96141767 | N39: -7.74 | O39: =M39*ENT+(1-M39)*USGS49 -> -8.2860793 | P39: =N39*0.001*AB$12+AB$12 -> 0.0019896798 | Q39: =((J39+L39)*N39-L39*ENT)/J39 -> -36.396389 | R39: =Q39-USGS49 -> 14.153611 | S39: -19.25 | T39: =174.3108-173.1998 -> 1.111 | U39: 1.488 | V39: =(((16/18)*K39/1000+(32/61)*T39/1000)*Q39-(16/18)*(K39/1000)*USGS49-(32/61)*(T39/1000)*S39)/4.93 -> 0.3042039 | W39: =V39*183.3/(4*16) -> 0.87125899 | X39: =1000000*W39/183.3 -> 4753.186 | AB39: Expt | AC39: time (d) | AD39: sqrt t | AE39: Δ18O shift | AF39: % replacement image
A40: W-2374 | B40: Zircon011 RP-9 | C40: 45486.574 | D40: -53.05 | E40: 0.09 | F40: -52.87 | G40: 0.25 | H40: -7.91 | I40: 0.02 | J40: =1901.4936-1785.9073 -> 115.5863 | K40: 120 | L40: 2400 | M40: =L40/(L40+J40) -> 0.95405194 | N40: -7.89 | O40: =M40*ENT+(1-M40)*USGS49 -> -8.6098765 | P40: =N40*0.001*AB$12+AB$12 -> 0.001989379 | Q40: =((J40+L40)*N40-L40*ENT)/J40 -> -34.882818 | R40: =Q40-USGS49 -> 15.667182 | S40: -19.25 | T40: =141.3287-140.1758 -> 1.1529 | U40: 1.488 | V40: =(((16/18)*K40/1000+(32/61)*T40/1000)*Q40-(16/18)*(K40/1000)*USGS49-(32/61)*(T40/1000)*S40)/4.93 -> 0.33706112 | W40: =V40*183.3/(4*16) -> 0.96536411 | X40: =1000000*W40/183.3 -> 5266.58 | AB40: Z_014 | AC40: 3 | AD40: =SQRT(AC40) -> 1.7320508 | AE40: =AVERAGE(R26:R27) -> 23.355922 | AF40: 15.29
...

Sheet SolbTable
A1: Sample ID | B1: Analysis_Date_Time | C1: d2H of injections | D1: d2H injections St Dev | E1: d2H of Analyses | F1: d2H injections St Dev2 | G1: d18O of injections | H1: d18O injections St Dev | I1: M Fl (mg) | J1: M USGS-49 (mg) | K1: M ENT (mg) | L1: XENT | M1: d18O Meas | N1: d18O Nominal | O1: (18O/16O)soln | P1: d18O Fl | Q1: Δ18O Fl | R1: d18O SiO2 | S1: M SiO2 (mg) | T1: M Qz sat. (mg) | U1: MO,MTZ (g) | V1: MMTZ (g) | W1: Solb (molality)
A2: Zir005 | B2: 45319.369 | C2: -52.07 | D2: 0.17 | E2: -52.22 | F2: 0.22 | G2: -7.63 | H2: 0.01 | I2: 91.9 | J2: 120 | K2: 2788.6 | L2: =K2/(K2+I2) -> 0.96809582 | M2: =G2 -> -7.63 | N2: =L2*ENT+(1-L2)*-5.72 -> -6.5622434 | O2: 0.0019899003 | P2: =((I2+K2)*M2-K2*ENT)/I2 -> -39.187606 | Q2: =P2-USGS49 -> 11.362394 | R2: -19.25 | S2: 1.3466 | T2: 0.017 | U2: =(((16/18)*J2/1000+(32/61)*S2/1000)*P2-(16/18)*(J2/1000)*USGS49-(32/61)*(S2/1000)*R2)/4.93 -> 0.24298266 | V2: =U2*183.3/(4*16) -> 0.69591751 | W2: =1000000*V2/183.3 -> 3796.604
A3: Zir006 | B3: 45319.269 | C3: -54.1 | D3: 0.01 | E3: -54.13 | F3: 0.04 | G3: -7.92 | H3: 0.01 | I3: 105.3 | J3: 120 | K3: 2323.4 | L3: =K3/(K3+I3) -> 0.95664347 | M3: =G3 -> -7.92 | N3: =L3*ENT+(1-L3)*-5.81 -> -6.5561819 | O3: 0.0019893389 | P3: =((I3+K3)*M3-K3*ENT)/I3 -> -37.265888 | Q3: =P3-USGS49 -> 13.284112 | R3: -19.25 | S3: 1.2353 | T3: 0.8712 | U3: =(((16/18)*J3/1000+(32/61)*S3/1000)*P3-(16/18)*(J3/1000)*USGS49-(32/61)*(S3/1000)*R3)/4.93 -> 0.28505014 | V3: =U3*183.3/(4*16) -> 0.81640141 | W3: =1000000*V3/183.3 -> 4453.9084
A4: Zir009 | B4: 45486.17 | C4: -40.45 | D4: 0.13 | E4: -40.34 | F4: 0.16 | G4: -7.71 | H4: 0.03 | I4: 104.0568 | J4: 120 | K4: 2400 | L4: =K4/(K4+I4) -> 0.95844471 | M4: =G4 -> -7.71 | N4: =L4*ENT+(1-L4)*USGS49 -> -8.4167704 | O4: 0.00198976 | P4: =((I4+K4)*M4-K4*ENT)/I4 -> -33.542046 | Q4: =P4-USGS49 -> 17.007954 | R4: -19.25 | S4: =115.9289-114.8693 -> 1.0596 | T4: 1.488 | U4: =(((16/18)*J4/1000+(32/61)*S4/1000)*P4-(16/18)*(J4/1000)*USGS49-(32/61)*(S4/1000)*R4)/4.93 -> 0.36637677 | V4: =U4*183.3/(4*16) -> 1.049326 | W4: =1000000*V4/183.3 -> 5724.6371
A5: Zir010 | B5: 45486.523 | C5: -43.12 | D5: 0.14 | E5: -42.95 | F5: 0.24 | G5: -7.77 | H5: 0.01 | I5: =1874.2572-1777.9436 -> 96.3136 | J5: 120 | K5: 2400 | L5: =K5/(K5+I5) -> 0.96141767 | M5: =G5 -> -7.77 | N5: =L5*ENT+(1-L5)*USGS49 -> -8.2860793 | O5: 0.0019896798 | P5: =((I5+K5)*M5-K5*ENT)/I5 -> -37.173947 | Q5: =P5-USGS49 -> 13.376053 | R5: -19.25 | S5: =174.3108-173.1998 -> 1.111 | T5: 1.488 | U5: =(((16/18)*J5/1000+(32/61)*S5/1000)*P5-(16/18)*(J5/1000)*USGS49-(32/61)*(S5/1000)*R5)/4.93 -> 0.28728855 | V5: =U5*183.3/(4*16) -> 0.82281236 | W5: =1000000*V5/183.3 -> 4488.8836
A6: Zir011 | B6: 45486.574 | C6: -53.05 | D6: 0.09 | E6: -52.87 | F6: 0.25 | G6: -7.91 | H6: 0.02 | I6: =1901.4936-1785.9073 -> 115.5863 | J6: 120 | K6: 2400 | L6: =K6/(K6+I6) -> 0.95405194 | M6: =G6 -> -7.91 | N6: =L6*ENT+(1-L6)*USGS49 -> -8.6098765 | O6: 0.001989379 | P6: =((I6+K6)*M6-K6*ENT)/I6 -> -35.318092 | Q6: =P6-USGS49 -> 15.231908 | R6: -19.25 | S6: =141.3287-140.1758 -> 1.1529 | T6: 1.488 | U6: =(((16/18)*J6/1000+(32/61)*S6/1000)*P6-(16/18)*(J6/1000)*USGS49-(32/61)*(S6/1000)*R6)/4.93 -> 0.32759002 | V6: =U6*183.3/(4*16) -> 0.9382383 | W6: =1000000*V6/183.3 -> 5118.5941
A7: Zir012 | B7: 45486.624 | C7: -49.39 | D7: 0.06 | E7: -49.26 | F7: 0.18 | G7: -8.07 | H7: 0.03 | I7: =1891.0933-1797.5914 -> 93.5019 | J7: 120 | K7: 2400 | L7: =K7/(K7+I7) -> 0.96250177 | M7: =G7 -> -8.07 | N7: =L7*ENT+(1-L7)*USGS49 -> -8.2384221 | O7: 0.0019890581 | P7: =((I7+K7)*M7-K7*ENT)/I7 -> -46.058533 | Q7: =P7-USGS49 -> 4.4914671 | R7: -19.25 | S7: 1.0481 | T7: 0.017 | U7: =(((16/18)*J7/1000+(32/61)*S7/1000)*P7-(16/18)*(J7/1000)*USGS49-(32/61)*(S7/1000)*R7)/4.93 -> 0.094188617 | V7: =U7*183.3/(4*16) -> 0.26976209 | W7: =1000000*V7/183.3 -> 1471.6971
A8: Zir023 | B8: 45806.078 | C8: -36.59 | D8: 0.06 | E8: -36.59 | G8: -5.96 | H8: 0.01 | I8: 60.9 | J8: 136.6 | K8: 2758.9 | L8: =K8/(K8+I8) -> 0.97840272 | M8: =G8 -> -5.96 | N8: =L8*ENT+(1-L8)*USGS49 -> -7.5394163 | O8: 0.001993249 | P8: =((I8+K8)*M8-K8*ENT)/I8 -> 22.580345 | Q8: =P8-USGS49 -> 73.130345 | R8: 20.77 | S8: 0.8577 | T8: 0.8712 | U8: =(((16/18)*J8/1000+(32/61)*S8/1000)*P8-(16/18)*(J8/1000)*USGS49-(32/61)*(S8/1000)*R8)/4.93 -> 1.8013111 | V8: =U8*183.3/(4*16) -> 5.1590675 | W8: =1000000*V8/183.3 -> 28145.485
A9: Zir024 | B9: 45806.138 | C9: -33.52 | D9: 0.04 | E9: -33.52 | G9: -5.61 | H9: 0.02 | I9: 30.4 | J9: 112.5 | K9: 2734.6 | L9: =K9/(K9+I9) -> 0.98900542 | M9: =G9 -> -5.61 | N9: =L9*ENT+(1-L9)*USGS49 -> -7.0733215 | O9: 0.0019939508 | P9: =((I9+K9)*M9-K9*ENT)/I9 -> 82.544868 | Q9: =P9-USGS49 -> 133.09487 | R9: 20.77 | S9: 0.6859 | T9: 0.8712 | U9: =(((16/18)*J9/1000+(32/61)*S9/1000)*P9-(16/18)*(J9/1000)*USGS49-(32/61)*(S9/1000)*R9)/4.93 -> 2.7042017 | V9: =U9*183.3/(4*16) -> 7.7450027 | W9: =1000000*V9/183.3 -> 42253.152
A10: Zir025 | B10: 45806.198 | C10: -30.97 | D10: 0.08 | E10: -30.97 | G10: -5.33 | H10: 0.02 | I10: 139.4 | J10: 129.2 | K10: 2648.2 | L10: =K10/(K10+I10) -> 0.94999283 | M10: =G10 -> -5.33 | N10: =L10*ENT+(1-L10)*USGS49 -> -8.7883154 | O10: 0.0019945123 | P10: =((I10+K10)*M10-K10*ENT)/I10 -> 18.606385 | Q10: =P10-USGS49 -> 69.156385 | R10: 20.77 | S10: 0.7708 | T10: 0.8712 | U10: =(((16/18)*J10/1000+(32/61)*S10/1000)*P10-(16/18)*(J10/1000)*USGS49-(32/61)*(S10/1000)*R10)/4.93 -> 1.6108218 | V10: =U10*183.3/(4*16) -> 4.6134944 | W10: =1000000*V10/183.3 -> 25169.091
A11: Zir026 | B11: 45806.259 | C11: -91.47 | D11: 0.22 | E11: -91.47 | G11: -15.84 | H11: 0.08 | I11: 84.7 | J11: 96.8 | K11: 290.6 | L11: =K11/(K11+I11) -> 0.77431388 | M11: =G11 -> -15.84 | N11: =L11*ENT+(1-L11)*USGS49 -> -16.511162 | O11: 0.0019734376 | P11: =((I11+K11)*M11-K11*ENT)/I11 -> -47.576128 | Q11: =P11-USGS49 -> 2.9738725 | R11: 20.77 | S11: 0.289 | T11: 0.5808 | U11: =(((16/18)*J11/1000+(32/61)*S11/1000)*P11-(16/18)*(J11/1000)*USGS49-(32/61)*(S11/1000)*R11)/4.93 -> 0.049801924 | V11: =U11*183.3/(4*16) -> 0.14263582 | W11: =1000000*V11/183.3 -> 778.15506
A12: Zir027 | B12: 45806.319 | C12: -30.28 | D12: 0.22 | E12: -30.28 | G12: -5.46 | H12: 0.04 | I12: 55.6 | J12: 92.1 | K12: 315.6 | L12: =K12/(K12+I12) -> 0.85021552 | M12: =G12 -> -5.46 | N12: =L12*ENT+(1-L12)*USGS49 -> -13.174526 | O12: 0.0019942516 | P12: =((I12+K12)*M12-K12*ENT)/I12 -> 0.95417266 | Q12: =P12-USGS49 -> 51.504173 | R12: 20.77 | S12: 0.8474 | T12: 0.8712 | U12: =(((16/18)*J12/1000+(32/61)*S12/1000)*P12-(16/18)*(J12/1000)*USGS49-(32/61)*(S12/1000)*R12)/4.93 -> 0.85348196 | V12: =U12*183.3/(4*16) -> 2.4444257 | W12: =1000000*V12/183.3 -> 13335.656

Sheet Ternary solutions
A1: Experiment | B1: M zir (mg)
A2: Zircon005 | B2: 80.75825 | C2: blank
A3: Zircon006 | B3: 107.3
A4: Zircon009 | B4: 138.06417
A5: Zircon010 | B5: 104.53889
A6: Zircon011 | B6: 137.29443
A7: Zircon012 | B7: 35.193324 | C7: blank
A8: Zircon014 | B8: 247.82133
A9: Zircon015 | B9: 1327.8217
A10: Zircon016 | B10: 159.34723
A11: Zircon017 | B11: 0.48477781
A12: Zircon019 | B12: 19.055129
A13: Zircon021 | B13: 654.79271
A14: Zircon022 | B14: 266.23048

Sheet Mix data
A1: Reported | E1: Rearranged
A2: =Data!B1 -> Sample ID | B2: =Data!N1 -> d18O Meas | C2: =Data!O1 -> d18O Nominal | E2: =Data!N1 -> d18O Meas | F2: =Data!O1 -> d18O Nominal
A3: =Data!B50 -> Mix 1:1 | B3: =Data!N50 -> -28.2 | C3: =Data!O50 -> -21.18472 | E3: =B3 -> -28.2 | F3: =C11 -> -28.57
A4: =Data!B51 -> Mix 1:1 | B4: =Data!N51 -> -28.2 | C4: =Data!O51 -> -21.18472 | E4: =B4 -> -28.2 | F4: =C12 -> -28.57
A5: =Data!B52 -> Mix 1:2 | B5: =Data!N52 -> -20.84 | C5: =Data!O52 -> -17.623785 | E5: =B5 -> -20.84 | F5: =C3 -> -21.18472
A6: =Data!B53 -> Mix 1:2 | B6: =Data!N53 -> -20.84 | C6: =Data!O53 -> -17.623785 | E6: =B6 -> -20.84 | F6: =C4 -> -21.18472
A7: =Data!B54 -> Mix 1:3_2 | B7: =Data!N54 -> -17.3 | C7: =Data!O54 -> -7.6621951 | E7: =B7 -> -17.3 | F7: =C$5 -> -17.623785
A8: =Data!B55 -> Mix 1:3_2 | B8: =Data!N55 -> -17.3 | C8: =Data!O55 -> -7.6621951 | E8: =B8 -> -17.3 | F8: =C$5 -> -17.623785
A9: =Data!B56 -> Mix 1:3 | B9: =Data!N56 -> -17.74 | C9: =Data!O56 -> -7.6621951 | E9: =B9 -> -17.74 | F9: =C$5 -> -17.623785
A10: =Data!B57 -> Mix 1:3 | B10: =Data!N57 -> -17.74 | C10: =Data!O57 -> -7.6621951 | E10: =B10 -> -17.74 | F10: =C$5 -> -17.623785
A11: =Data!B58 -> Mix 1:4 | B11: =Data!N58 -> -15.29 | C11: =Data!O58 -> -28.57 | E11: =B11 -> -15.29 | F11: ?
A12: =Data!B59 -> Mix 1:4 | B12: =Data!N59 -> -15.29 | C12: =Data!O59 -> -28.57 | E12: =B12 -> -15.29 | F12: ?
